Workbook
Name CF_AdminMode: '(Options)'!$B$11
Name CF_AllocateFirstRoleEffortsToOtherRoles: '(Options)'!$B$7
Name CF_Currency: '(Options)'!$B$3
Name CF_FTEdays: '(Options)'!$B$8
Name CF_IncludeInflation: '(Options)'!$B$5
Name CF_LinkManual: '(Options)'!$B$13
Name CF_LinkManualGerman: '(Options)'!$B$14
Name CF_LinkTeams: '(Options)'!$B$16
Name CF_ManualTableOfContents: '(Options)'!$B$15
Name CF_NoPriorSortedTasksGANTT: '(Options)'!$B$6
Name CF_TimePeriodType: '(Options)'!$B$4
Name CO_FirstRow: 'Other costs'!$A$5
Name CO_HeaderAssumptions: 'Other costs'!$C$4
Name CO_HeaderCosts: 'Other costs'!$D$4
Name CO_HeaderDescr: 'Other costs'!$B$4
Name CO_HeaderHandlingFee: 'Other costs'!#REF!
Name CO_HeaderID: 'Other costs'!$A$4
Name CO_HeaderPrice: 'Other costs'!$E$4
Name CO_LastRow: 'Other costs'!$A$36
Name FT_ChangedFeatureTasks: Features!$E$2
Name FT_EstimationMethod: Features!$G$3
Name FT_FirstRow: Features!$A$10
Name FT_HeaderAssumptions: Features!$H$8
Name FT_HeaderDescription: Features!$G$8
Name FT_HeaderEffort: Features!$Q$8
Name FT_HeaderFeature: Features!$E$8
Name FT_HeaderGroup: Features!$C$8
Name FT_HeaderPos: Features!$A$8
Name FT_HeaderRangeQuery: Features!$B$8
Name FT_HeaderRefID: Features!$J$8
Name FT_HeaderRisks: Features!$I$8
Name FT_HeaderStoryPoints: Features!$M$8
Name FT_HeaderSubFeature: Features!$F$8
Name FT_HeaderSubGroup: Features!$D$8
Name FT_HeaderThreeEfforts: Features!$N$8:$P$8
Name FT_HeaderTShirtSizes: Features!$L$8
Name FT_IndividualAveragePercentage: Features!$R$3:$AA$3
Name FT_InputAssistanceMethod: Features!$G$4
Name FT_KeyTaskFlags: Features!$R$5:$AA$5
Name FT_LastRow: Features!$A$56
Name FT_MethodCols: Features!$L$7:$P$7
Name FT_Tasks: Features!$R$8:$AA$8
Name FT_TotalEffort: Features!$Q$9
Name GC_HeaderDependency: 'Chart | GANTT'!$G$4
Name GC_HeaderDuration: 'Chart | GANTT'!$F$4
Name GC_HeaderFinish: 'Chart | GANTT'!$H$4
Name GC_HeaderFirstPeriod: 'Chart | GANTT'!$I$4
Name GC_HeaderID: 'Chart | GANTT'!$C$4
Name GC_HeaderStart: 'Chart | GANTT'!$E$4
Name GC_HeaderSummaryTask: 'Chart | GANTT'!$B$4
Name GC_HeaderTask: 'Chart | GANTT'!$D$4
Name GC_HeaderTaskGroup: 'Chart | GANTT'!$A$4
Name GT_Efforts: 'Project tasks'!#REF!
Name GT_EffortsRisks: 'Project tasks'!$W$75:$AZ$75
Name GT_EffortsTravelTime: 'Project tasks'!$W$73:$AZ$73
Name GT_EffortsWarranty: 'Project tasks'!$W$74:$AZ$74
Name GT_EffortsWithoutWAAndTTAndRisks: 'Project tasks'!$W$77:$AZ$77
Name GT_EffortWithoutWAAndTTAndRisks: 'Project tasks'!$J$77
Name GT_FinishDateGANTT: 'Project tasks'!$Q$70
Name GT_FirstRow: 'Project tasks'!$A$12

Sheet Start
A1: adesso calculator | B1: Manual: see menu item above "Show manual" or click this hyperlink
A2: =B17 | B2: Excel Macros are deactivated and you can't see the menu group above "adesso calculator"? In this case you have to configure the workbook security settings - please have a look at the manual!
A3: Tool version: | B3: 2.01 / 28.03.2025
A4: Last change in this document: | B4: =MAX(tblHistoryOfChanges[Date of change])
B5: see details in sheet "History of changes"
A6: Basic settings
B7: Advanced settings: see menu item above "Edit options"
A8: Proposal title: | B8: Locarno Film Festival - Drupal CMS 2.0 Relaunch
A9: Contract type: | B9: Work contract (fixed price)
A10: Customer: | B10: Locarno Film Festival
A11: Contractor (offering company): | B11: adesso Schweiz AG
A12: Accounting-related company: | B12: 2025-01
B13: Drupal 11 with Drupal CMS 2.0
A14: Calculation template: | B14: general_dev_de
B15: Please use menu above "Import" -> "Import from internal template" if you want to change the template.
A16: Calculation process: | B16: Calculation with two teams
A17: Current step of process: | B17: Preparation
B18: Not sure which process you should choose? Please have a look at the manual!
A19: adesso calculation team
A21: Please use the tabulator key in the last column of the last row for adding a new row.
A22: Team member | B22: Team member role in proposal process

Sheet Features
Q1: =SUM(R1:AA1)
A2: Features (Requirements/Deliverables) | E2: yes | G2: Use these options for calculating efforts. Please have a look at the manual! | Q2: Discuss the percentages with your team!
A3: =Start!A2 | F3: Estimation method: | G3: No specific method | Q3: Forecasted percentages: | R3: 0.25 | S3: 0.5 | T3: 0.15 | U3: 0.1 | V3: 0 | W3: 0 | X3: 0 | Y3: 0 | Z3: 0 | AA3: 0 | AB3: =SUM(FT_IndividualAveragePercentage)
F4: Input assistance for task values: | G4: No assistance | Q4: Actual percentages: | R4: =IFERROR(R9/$Q$9,0) | S4: =IFERROR(S9/$Q$9,0) | T4: =IFERROR(T9/$Q$9,0) | U4: =IFERROR(U9/$Q$9,0) | V4: =IFERROR(V9/$Q$9,0) | W4: =IFERROR(W9/$Q$9,0) | X4: =IFERROR(X9/$Q$9,0) | Y4: =IFERROR(Y9/$Q$9,0) | ... AA4: =IFERROR(AA9/$Q$9,0) | AB4: =SUM(FT_IndividualAveragePercentage)
Q5: Key task (for assistance): | R5: no | S5: yes | T5: no | U5: no | V5: no | W5: no | X5: no | Y5: no | Z5: no | AA5: no
B6: Use this column for special feature queries | D6: Feature group and sub group columns | I6: Use the menu above | R6: Use menu above "Edit feature task" for adding, renaming or reordering feature tasks.
B7: project task sheet. | D7: are optional! | I7: for adding or deleting risks! | L7: T-shirt sizing | M7: Planning poker | N7: Three-point estimation | O7: Three-point estimation | P7: Three-point estimation | R7: FT#1 | S7: FT#2 | T7: FT#3 | U7: FT#4 | V7: FT#5 | W7: FT#6 | X7: FT#7 | Y7: FT#8 | Z7: FT#9 | AA7: FT#10
A8: F-1 | B8: Homepage | C8: Website entry point with hero, featured content | D8: H | E8: 40 | F8: Sub feature title | G8: (Sub-)Feature description | H8: Assumptions | I8: Risks | J8: Ref. ID | L8: T-shirt size | M8: Story points | N8: Optimistic effort | O8: Realistic effort | P8: Pessimistic effort | Q8: Effort total | R8: Analyse & Software Design | S8: Software-entwicklung | T8: Softwaretest | U8: Fehlerbearb. nach BzA
A9: F-2 | B9: Film Program Page | C9: Dynamic festival program with filters | D9: H | E9: 60 | N9: =SUBTOTAL(9,N10:N10012) | O9: =SUBTOTAL(9,O10:O10012) | P9: =SUBTOTAL(9,P10:P10012) | Q9: =SUBTOTAL(9,Q10:Q10012) | R9: =SUBTOTAL(9,R10:R10012) | S9: =SUBTOTAL(9,S10:S10012) | T9: =SUBTOTAL(9,T10:T10012) | U9: =SUBTOTAL(9,U10:U10012) | ... AA9: =SUBTOTAL(9,AA10:AA10012)
A10: F-3 | B10: Film Archive | C10: Historical film database with search | D10: H | E10: 50
A11: F-4 | B11: Film Detail Page | C11: Individual film presentation | D11: M | E11: 30 | Q11: =SUM(R11:AA11)
A12: F-5 | B12: News & Updates | C12: News listing and detail pages | D12: M | E12: 25 | Q12: =SUM(R12:AA12)
A13: F-6 | B13: Event Landing Page | C13: Festival events and schedule | D13: M | E13: 35 | Q13: =SUM(R13:AA13)
A14: F-7 | B14: Press & Media | C14: Press releases and media kit | D14: L | E14: 20 | Q14: =SUM(R14:AA14)
A15: F-8 | B15: Partner & Sponsor | C15: Partner listings and logos | D15: L | E15: 15 | Q15: =SUM(R15:AA15)
A16: F-9 | B16: About Festival | C16: History, mission, team pages | D16: M | E16: 25 | Q16: =SUM(R16:AA16)
A17: F-10 | B17: Industry Section | C17: Professional accreditation area | D17: H | E17: 45 | Q17: =SUM(R17:AA17)
A18: F-11 | B18: Educational Programs | C18: Workshops and masterclasses | D18: M | E18: 30 | Q18: =SUM(R18:AA18)
A19: F-12 | B19: Venue Information | C19: Theater locations and facilities | D19: L | E19: 18 | Q19: =SUM(R19:AA19)
A20: F-13 | B20: Ticketing Integration | C20: Ticket purchase and booking | D20: H | E20: 55 | Q20: =SUM(R20:AA20)
A21: F-14 | B21: User Profile (Keycloak SSO) | C21: User account and preferences | D21: H | E21: 40 | Q21: =SUM(R21:AA21)
A22: F-15 | B22: VOD Streaming Pages | C22: Sony VOD integration | D22: H | E22: 50 | Q22: =SUM(R22:AA22)
... A55: F-48 | B55: Icon Feature List | C55: Feature highlights | D55: L | E55: 6 | Q55: =SUM(R55:AA55)
A56: F-49 | B56: Before/After Slider | C56: Image comparison | D56: M | E56: 10
A57: F-50 | B57: Custom HTML Block | C57: Flexible HTML content | D57: L | E57: 4
A58: F-51 | B58: Divider/Spacer | C58: Visual separators | D58: L | E58: 2
A59: F-52 | B59: Anchor Links | C59: In-page navigation | D59: L | E59: 4

Sheet Project tasks
J1: 0 | K1: no | N1: {=IFERROR(calcDefaultValueOfProjectTask(M1),"error")} | V1: =IF(J1<>"",IFERROR(J1-SUM(W1:AZ1),0),"")
A2: Project tasks (Work breakdown structure) | L2: Forecasted project length: | M2: 20 | N2: =(GT_FinishDateGANTT-GT_StartDateGANTT)/7 | W2: =IFERROR(W11/(GT_ProjectLength/52*CF_FTEdays),0) | X2: =IFERROR(X11/(GT_ProjectLength/52*CF_FTEdays),0) | Y2: =IFERROR(Y11/(GT_ProjectLength/52*CF_FTEdays),0) | Z2: =IFERROR(Z11/(GT_ProjectLength/52*CF_FTEdays),0) | AA2: =IFERROR(AA11/(GT_ProjectLength/52*CF_FTEdays),0) | AB2: =IFERROR(AB11/(GT_ProjectLength/52*CF_FTEdays),0) | AC2: =IFERROR(AC11/(GT_ProjectLength/52*CF_FTEdays),0) | AD2: =IFERROR(AD11/(GT_ProjectLength/52*CF_FTEdays),0) | ... AZ2: =IFERROR(AZ11/(GT_ProjectLength/52*CF_FTEdays),0) | BA2: =SUM(GT_ProjectRolesFTE)
W3: 1 | X3: 2 | Y3: 3 | Z3: 4 | AA3: 5 | AB3: 6 | AC3: 7 | AD3: 8 | AE3: 9 | AF3: 10 | AG3: 11 | AH3: 12 | AI3: 13 | AJ3: 14 | AK3: 15 | AL3: 16 | AM3: 17 | AN3: 18 | AO3: 19 | AP3: 20 | AQ3: 21 | AR3: 22 | AS3: 23 | AT3: 24 | AU3: 25 | AV3: 26 | AW3: 27 | AX3: 28 | AY3: 29 | AZ3: 30
W4: 1 | X4: 2 | Y4: 3 | Z4: 4 | AA4: 5 | AB4: 6 | AC4: 7 | AD4: 8 | AE4: 9
A5: =Start!A2 | L5: Forecasted team size: | M5: 0 | N5: =BA2 | V5: Use menu item above "Edit project roles" for adding, renaming or rearranging project roles. Red color = error! | W5: Any role | X5: Project manager | Y5: Software architect | Z5: Requirement Engineer | AA5: UI/UX Designer | AB5: Test manager | AC5: Test Engineer | AD5: Developer | AE5: DevOps Engineer
L6: Forecasted num of iterations: | M6: 0 | N6: e.g. sprints or releases
I7: Red color = error! | M7: Please update these values if you use the variables [#projectlength], [#teamsize], [#iterations] or [#sprints] in your formulas.
A8: T-1 | B8: Setup & Kickoff | C8: Project kickoff meeting and planning | D8: PM | E8: 8 | G8: Use menu above für special feature query! | H8: Use menu above for adding or deleting risks! | I8: Feature effort (FT): | J8: =SUMIFS($J:$J,$G:$G,"FT*") | L8: You only need these columns to use formulas. | P8: You only need these columns to create a GANTT chart and for a time period-related cost and capacity calculation. Please have a look at the manual!
A9: T-2 | B9: Setup & Kickoff | C9: DDEV local dev environment setup | D9: Backend | E9: 4
A10: T-3 | B10: Setup & Kickoff | C10: Azure infrastructure provisioning | D10: DevOps | E10: 16 | F10: Assumptions | G10: Special task or feature query | H10: Risks | I10: Ref. ID | J10: Effort | K10: Use formula? | L10: Variable | M10: Formula | N10: Result of formula | P10: Start | Q10: Finish | R10: Duration | S10: Dependency | T10: Show in GANTT? | V10: Not allocated effort
A11: T-4 | B11: Setup & Kickoff | C11: CI/CD pipeline configuration | D11: DevOps | E11: 12 | J11: =SUBTOTAL(9,J12:J69) | P11: =MIN(P12:P69) | Q11: =MAX(Q12:Q69) | R11: =Q11-P11 | V11: =SUBTOTAL(9,V12:V69) | W11: =SUBTOTAL(9,W12:W69) | X11: =SUBTOTAL(9,X12:X69) | Y11: =SUBTOTAL(9,Y12:Y69) | Z11: =SUBTOTAL(9,Z12:Z69) | AA11: =SUBTOTAL(9,AA12:AA69) | AB11: =SUBTOTAL(9,AB12:AB69) | AC11: =SUBTOTAL(9,AC12:AC69) | ... AZ11: =SUBTOTAL(9,AZ12:AZ69)
A12: T-5 | B12: Setup & Kickoff | C12: Git repository and branching strategy | D12: Backend | E12: 4 | J12: Use key "f" for formula | M12: For experts only! See manual!
A13: T-6 | B13: Content Architecture | C13: Content type modeling (17 types) | D13: Backend | E13: 40 | J13: 0 | K13: no | N13: {=IFERROR(calcDefaultValueOfProjectTask(M13),"error")} | T13: no | V13: =IF(J13<>"",IFERROR(J13-SUM(W13:AZ13),0),"") | X13: =100%*$J$13
A14: T-7 | B14: Content Architecture | C14: Paragraph component development (35 types) | D14: Backend | E14: 80 | J14: 0 | K14: no | N14: {=IFERROR(calcDefaultValueOfProjectTask(M14),"error")} | T14: no | V14: =IF(J14<>"",IFERROR(J14-SUM(W14:AZ14),0),"") | X14: =100%*$J$14
A15: T-8 | B15: Content Architecture | C15: Taxonomy vocabularies setup | D15: Backend | E15: 12 | J15: 0 | K15: no | N15: {=IFERROR(calcDefaultValueOfProjectTask(M15),"error")} | T15: no | V15: =IF(J15<>"",IFERROR(J15-SUM(W15:AZ15),0),"") | Y15: =100%*$J$15
A16: T-9 | B16: Content Architecture | C16: Views and listing pages | D16: Backend | E16: 30 | J16: 0 | K16: no | N16: {=IFERROR(calcDefaultValueOfProjectTask(M16),"error")} | T16: no | V16: =IF(J16<>"",IFERROR(J16-SUM(W16:AZ16),0),"") | AB16: =100%*$J$16
A17: T-10 | B17: Content Architecture | C17: Custom fields and field formatters | D17: Backend | E17: 20 | J17: 0 | K17: no | N17: {=IFERROR(calcDefaultValueOfProjectTask(M17),"error")} | T17: no | V17: =IF(J17<>"",IFERROR(J17-SUM(W17:AZ17),0),"")
A18: T-11 | B18: Frontend & Theming | C18: Mercury Theme setup | D18: Frontend | E18: 8 | J18: 0 | K18: no | N18: {=IFERROR(calcDefaultValueOfProjectTask(M18),"error")} | T18: no | V18: =IF(J18<>"",IFERROR(J18-SUM(W18:AZ18),0),"") | AE18: =100%*$J$18
A19: T-12 | B19: Frontend & Theming | C19: Storybook component development | D19: Frontend | E19: 60 | J19: 0 | K19: no | N19: {=IFERROR(calcDefaultValueOfProjectTask(M19),"error")} | T19: no | V19: =IF(J19<>"",IFERROR(J19-SUM(W19:AZ19),0),"")
A20: T-13 | B20: Frontend & Theming | C20: Tailwind CSS configuration | D20: Frontend | E20: 12 | G20: FT#1 | J20: =Features!R9 | L20: [design] | N20: {=IFERROR(calcDefaultValueOfProjectTask(M20),"error")} | T20: no | V20: =IF(J20<>"",IFERROR(J20-SUM(W20:AZ20),0),"") | Y20: =20%*$J$20 | Z20: =80%*$J$20
A21: T-14 | B21: Frontend & Theming | C21: Responsive design implementation | D21: Frontend | E21: 40 | G21: FT#2 | J21: =Features!S9 | L21: [dev] | N21: {=IFERROR(calcDefaultValueOfProjectTask(M21),"error")} | T21: no | V21: =IF(J21<>"",IFERROR(J21-SUM(W21:AZ21),0),"") | AD21: =100%*$J$21
A22: T-15 | B22: Frontend & Theming | C22: Accessibility (WCAG 2.1 AA) | D22: Frontend | E22: 24 | G22: FT#3 | J22: =Features!T9 | L22: [test] | N22: {=IFERROR(calcDefaultValueOfProjectTask(M22),"error")} | T22: no | V22: =IF(J22<>"",IFERROR(J22-SUM(W22:AZ22),0),"") | AC22: =100%*$J$22
A23: T-16 | B23: Integrations | C23: Keycloak oAuth2 SSO integration | D23: Backend | E23: 40 | J23: 0 | K23: no | N23: {=IFERROR(calcDefaultValueOfProjectTask(M23),"error")} | T23: no | V23: =IF(J23<>"",IFERROR(J23-SUM(W23:AZ23),0),"") | AB23: =20%*$J$23 | AC23: =80%*$J$23
A24: T-17 | B24: Integrations | C24: Fiona Festival API integration | D24: Backend | E24: 60 | J24: 0 | K24: no | N24: {=IFERROR(calcDefaultValueOfProjectTask(M24),"error")} | T24: no | V24: =IF(J24<>"",IFERROR(J24-SUM(W24:AZ24),0),"") | Y24: =20%*$J$24 | AE24: =80%*$J$24
A25: T-18 | B25: Integrations | C25: Sony VOD DRM streaming | D25: Backend | E25: 50 | J25: 0 | K25: no | N25: {=IFERROR(calcDefaultValueOfProjectTask(M25),"error")} | T25: no | V25: =IF(J25<>"",IFERROR(J25-SUM(W25:AZ25),0),"") | Y25: =20%*$J$25 | AE25: =80%*$J$25
A26: T-19 | B26: Integrations | C26: Mobile App REST API | D26: Backend | E26: 35 | J26: 0 | K26: no | N26: {=IFERROR(calcDefaultValueOfProjectTask(M26),"error")} | T26: no | V26: =IF(J26<>"",IFERROR(J26-SUM(W26:AZ26),0),"") | Z26: =100%*$J$26
A27: T-20 | B27: Integrations | C27: Solr Enterprise Search setup | D27: Backend | E27: 40 | J27: 0 | K27: no | N27: {=IFERROR(calcDefaultValueOfProjectTask(M27),"error")} | T27: no | V27: =IF(J27<>"",IFERROR(J27-SUM(W27:AZ27),0),"") | Z27: =100%*$J$27
A28: T-21 | B28: Integrations | C28: CloudFront CDN configuration | D28: DevOps | E28: 16 | G28: FT#4 | J28: =Features!U9 | L28: [bugfix] | N28: {=IFERROR(calcDefaultValueOfProjectTask(M28),"error")} | T28: no | V28: =IF(J28<>"",IFERROR(J28-SUM(W28:AZ28),0),"") | AC28: =20%*$J$28 | AD28: =80%*$J$28
A29: T-22 | B29: Migration | C29: Content migration scripts | D29: Backend | E29: 40 | J29: 0 | K29: no | N29: {=IFERROR(calcDefaultValueOfProjectTask(M29),"error")} | T29: no | V29: =IF(J29<>"",IFERROR(J29-SUM(W29:AZ29),0),"") | Z29: =50%*$J$29 | AD29: =50%*$J$29
A30: T-23 | B30: Migration | C30: Asset migration (images/videos) | D30: Backend | E30: 20 | J30: 0 | K30: no | N30: {=IFERROR(calcDefaultValueOfProjectTask(M30),"error")} | T30: no | V30: =IF(J30<>"",IFERROR(J30-SUM(W30:AZ30),0),"") | AE30: =100%*$J$30
A31: T-24 | B31: Migration | C31: User account migration | D31: Backend | E31: 16 | J31: 0 | K31: no | N31: {=IFERROR(calcDefaultValueOfProjectTask(M31),"error")} | T31: no | V31: =IF(J31<>"",IFERROR(J31-SUM(W31:AZ31),0),"")
A32: T-25 | B32: Migration | C32: URL redirects (301) | D32: Backend | E32: 12 | J32: 0 | K32: no | N32: {=IFERROR(calcDefaultValueOfProjectTask(M32),"error")} | T32: no | V32: =IF(J32<>"",IFERROR(J32-SUM(W32:AZ32),0),"")
A33: T-26 | B33: Migration | C33: Data validation and cleanup | D33: Backend | E33: 20 | J33: 0 | K33: no | N33: {=IFERROR(calcDefaultValueOfProjectTask(M33),"error")} | T33: no | V33: =IF(J33<>"",IFERROR(J33-SUM(W33:AZ33),0),"")
A34: T-27 | B34: Testing & QA | C34: Unit test development | D34: QA | E34: 30 | J34: 0 | K34: yes | M34: max([#projectlength]*ifs([#total1]<200,0.5,[#total1]<500,1,[#total1]<1000,1.5,[#total1]<2000,2,true,3),10%*[#total1]) | N34: {=IFERROR(calcDefaultValueOfProjectTask(M34),"error")} | T34: no | V34: =IF(J34<>"",IFERROR(J34-SUM(W34:AZ34),0),"") | X34: =100%*$J$34
A35: T-28 | B35: Testing & QA | C35: Integration testing | D35: QA | E35: 25 | J35: 0 | K35: no | N35: {=IFERROR(calcDefaultValueOfProjectTask(M35),"error")} | T35: no | V35: =IF(J35<>"",IFERROR(J35-SUM(W35:AZ35),0),"") | AB35: =100%*$J$35
A36: T-29 | B36: Testing & QA | C36: E2E testing (Playwright) | D36: QA | E36: 30 | J36: 0 | K36: no | N36: {=IFERROR(calcDefaultValueOfProjectTask(M36),"error")} | T36: no | V36: =IF(J36<>"",IFERROR(J36-SUM(W36:AZ36),0),"") | Y36: =100%*$J$36
A37: T-30 | B37: Testing & QA | C37: Performance testing | D37: QA | E37: 16 | J37: 0 | K37: no | N37: {=IFERROR(calcDefaultValueOfProjectTask(M37),"error")} | T37: no | V37: =IF(J37<>"",IFERROR(J37-SUM(W37:AZ37),0),"") | AE37: =100%*$J$37
A38: T-31 | B38: Testing & QA | C38: Security audit | D38: QA | E38: 16 | J38: 0 | K38: no | N38: {=IFERROR(calcDefaultValueOfProjectTask(M38),"error")} | T38: no | V38: =IF(J38<>"",IFERROR(J38-SUM(W38:AZ38),0),"") | X38: =100%*$J$38
A39: T-32 | B39: Testing & QA | C39: UAT coordination | D39: PM | E39: 12 | J39: 0 | K39: no | N39: {=IFERROR(calcDefaultValueOfProjectTask(M39),"error")} | T39: no | V39: =IF(J39<>"",IFERROR(J39-SUM(W39:AZ39),0),"") | W39: =100%*$J$39
A40: T-33 | B40: Deployment | C40: Staging deployment | D40: DevOps | E40: 8 | G40: TT | J40: 0 | K40: no | L40: [traveltime] | N40: {=IFERROR(calcDefaultValueOfProjectTask(M40),"error")} | T40: no | V40: =IF(J40<>"",IFERROR(J40-SUM(W40:AZ40),0),"") | W40: =100%*$J$40
...

Sheet Milestones
A1: Payment milestones
A2: =Start!A2
A4: Milestone | B4: Title | C4: Effort | D4: Date | E4: Depencency
A5: M1 | B5: BzA Modul 1 | E5: eot(P-40)
A6: M2 | B6: Abnahme Modul 1 | E6: eot(P-55)
A11: Milestone | B11: Title | C11: Task group | D11: Summary task | E11: Percentage
A12: M1 | B12: BzA Modul 1 | C12: TP1 | D12: Initialisierung TP1 | E12: 1
A13: M1 | B13: BzA Modul 1 | C13: TP1 | D13: Modul 1 | E13: 0.8
A14: M1 | B14: BzA Modul 1 | C14: Querschnitt | E14: anteilig
A15: M2 | B15: Abnahme Modul 1 | C15: TP1 | D15: Modul 1 | E15: 0.2

Sheet Project risks
G1: =IFERROR(E1*F1,0)
A2: Project risk analysis
A3: =Start!A2
A5: ID | B5: Risk title | C5: Risk description | D5: Risk source (Linked feature ID or project task ID) | E5: Risk likelihood | F5: Risk impact | G5: Weighted risk impact
F6: =SUBTOTAL(9,F7:F33) | G6: =SUBTOTAL(9,G7:G33)
A7: First row. Don't override this row. Please insert new rows after this row! Don't insert or delete rows manually! Only use the menu items above "Insert row" and "Delete row" or short keys CTRL+ or CTRL-.
A8: R-1 | B8: Fiona API changes | C8: External festival API modifications during development | D8: Medium | E8: High | F8: Version locking, abstraction layer, vendor communication | G8: =IFERROR(E8*F8,0)
A9: R-2 | B9: Keycloak SSO complexity | C9: OAuth2 integration more complex than anticipated | D9: Medium | E9: Medium | F9: Early prototype, security expert consultation | G9: =IFERROR(E9*F9,0)
A10: R-3 | B10: Sony VOD DRM requirements | C10: Streaming DRM implementation challenges | D10: High | E10: High | F10: POC before commitment, vendor support contract | G10: =IFERROR(E10*F10,0)
A11: R-4 | B11: Solr search performance | C11: Enterprise search scalability under load | D11: Medium | E11: High | F11: Load testing, caching strategy, index optimization | G11: =IFERROR(E11*F11,0)
A12: R-5 | B12: Migration data quality | C12: Legacy content requires significant cleanup | D12: High | E12: Medium | F12: Early migration tests, data validation scripts | G12: =IFERROR(E12*F12,0)
A13: R-6 | B13: Third-party dependencies | C13: Critical modules become unmaintained | D13: Low | E13: High | F13: Alternative module research, update monitoring | G13: =IFERROR(E13*F13,0)
A14: R-7 | B14: Azure cost overruns | C14: Higher than expected cloud infrastructure costs | D14: Medium | E14: Medium | F14: Cost monitoring, auto-scaling limits, budget alerts | G14: =IFERROR(E14*F14,0)
A15: R-8 | B15: Browser compatibility | C15: Cross-browser issues in complex components | D15: Medium | E15: Low | F15: Early browser testing, progressive enhancement | G15: =IFERROR(E15*F15,0)
A16: R-9 | B16: Performance targets | C16: Page load times exceed 2-second target | D16: Medium | E16: High | F16: Performance budget, CDN optimization, lazy loading | G16: =IFERROR(E16*F16,0)
A17: R-10 | B17: Accessibility compliance | C17: WCAG 2.1 AA compliance gaps discovered late | D17: Low | E17: High | F17: Automated testing from start, accessibility audit | G17: =IFERROR(E17*F17,0)
A18: R-11 | B18: Scope creep | C18: Uncontrolled feature additions during development | D18: High | E18: Medium | F18: Change request process, backlog prioritization | G18: =IFERROR(E18*F18,0)
A19: R-12 | B19: Resource availability | C19: Key team members unavailable during critical phases | D19: Medium | E19: High | F19: Knowledge sharing, documentation, backup resources | G19: =IFERROR(E19*F19,0)
G20: =IFERROR(E20*F20,0)
G21: =IFERROR(E21*F21,0)
G22: =IFERROR(E22*F22,0)
G23: =IFERROR(E23*F23,0)
G24: =IFERROR(E24*F24,0)
G25: =IFERROR(E25*F25,0)
G26: =IFERROR(E26*F26,0)
G27: =IFERROR(E27*F27,0)
G28: =IFERROR(E28*F28,0)
G29: =IFERROR(E29*F29,0)
G30: =IFERROR(E30*F30,0)
G31: =IFERROR(E31*F31,0)
G32: =IFERROR(E32*F32,0)
A33: Last row. Don't override this row. Please insert new rows before this row! Don't insert or delete rows manually! Only use the menu items above "Insert row" and "Delete row" or short keys CTRL+ or CTRL-.

Sheet Project roles
G1: any | H1: =_xlfn.XLOOKUP(G1,tblCompanies[Company],tblCompanies[Accounting-related company],"") | I1: any | J1: =_xlfn.XLOOKUP(I1,tblCountries[Country],tblCountries[Inflation rate],0) | K1: any | L1: any | N1: =SUMIFS(tblDataPool[Effort],tblDataPool[Project Role],B1,tblDataPool[Sub role],E1)-T1 | O1: =SUMIFS(tblDataPool[Costs],tblDataPool[Project Role],B1,tblDataPool[Sub role],E1)-U1 | P1: 0 | Q1: =SUMIFS(tblDataPool[Price],tblDataPool[Project Role],B1,tblDataPool[Sub role],E1)-W1 | R1: 0 | T1: =SUMIFS(tblDataPool[Effort],tblDataPool[Project Role],B1,tblDataPool[Sub role],E1,tblDataPool[Item type],"Travel time") | U1: =SUMIFS(tblDataPool[Costs],tblDataPool[Project Role],B1,tblDataPool[Sub role],E1,tblDataPool[Item type],"Travel time") | V1: =P1 | W1: =SUMIFS(tblDataPool[Price],tblDataPool[Project Role],B1,tblDataPool[Sub role],E1,tblDataPool[Item type],"Travel time") | X1: 0 | Z1: =Q1+W1-O1-U1 | AA1: =IF(OR(ST_Contractor=G1,AND(ST_AccountingRelatedCompany="yes",H1="yes")),Q1+W1,Z1) | AB1: =IF(OR(ST_Contractor=G1,AND(ST_AccountingRelatedCompany="yes",H1="yes")),N1+T1,0) | AC1: =IF(AB1>0,AA1/AB1,0)
B2: Projectroles and pricing
B3: =Start!A2
B5: Only use menu item above "Edit project roles" or "Edit sub roles" for adding, renaming or rearranging project roles or sub roles. New rows cannot be inserted or deleted manually! | N5: Use the menu item above "Recalculate role sheet" or "Refresh tables/charts" to recalculate the efforts.
G6: Role details | N6: Daily rates and costs of project roles (without travel) | T6: Daily rates and costs of travel time
A7: Role ID | B7: Project Role | C7: ColNo | D7: Sub Role ID | E7: Sub role | F7: Percentage | G7: Company | H7: Accounting-related company | I7: Country | J7: Inflation rate p.a. | K7: Location | L7: Seniority Level | N7: Effort | O7: ="Costs [" & CF_Currency & "]" | P7: ="Daily costs [" & CF_Currency & "]" | Q7: ="Price [" & CF_Currency & "]" | R7: ="Daily rate [" & CF_Currency & "]" | T7: Travel time | U7: ="Costs [" & CF_Currency & "]" | V7: ="Daily costs [" & CF_Currency & "]" | W7: ="Price [" & CF_Currency & "]" | X7: ="Daily rate [" & CF_Currency & "]" | Z7: ="Margin [" & CF_Currency & "]" | AA7: ="Gross profit [" & CF_Currency & "]" | AB7: Effort of contractor | AC7: ="Gross profit ratio [" & CF_Currency & "/day]"
A8: R-1 | B8: Project manager | C8: Senior | D8: Responsible for overall project delivery, stakeholder communication, timeline and budget management | E8: 0.3 | N8: =SUM(N9:N27) | O8: =SUM(O9:O27) | P8: =IFERROR(O8/N8,0) | Q8: =SUM(Q9:Q27) | R8: =IFERROR(Q8/(N8-'Project tasks'!J76),0) | T8: =SUM(T9:T27) | U8: =SUM(U9:U27) | V8: =IFERROR(U8/T8,0) | W8: =SUM(W9:W27) | X8: =IFERROR(W8/T8,0) | Z8: =SUM(Z9:Z27) | AA8: =SUM(AA9:AA27) | AB8: =SUM(AB9:AB27) | AC8: =IF(AB8>0,AA8/AB8,0)
A9: R-2 | B9: Software architect | C9: Expert | D9: Technical lead, system architecture design, code reviews, integration strategy | E9: 0.5 | F9: 1 | G9: any | H9: =_xlfn.XLOOKUP(G9,tblCompanies[Company],tblCompanies[Accounting-related company],"") | I9: any | J9: =_xlfn.XLOOKUP(I9,tblCountries[Country],tblCountries[Inflation rate],0) | K9: any | L9: any | N9: =SUMIFS(tblDataPool[Effort],tblDataPool[Project Role],B9,tblDataPool[Sub role],E9)-T9 | O9: =SUMIFS(tblDataPool[Costs],tblDataPool[Project Role],B9,tblDataPool[Sub role],E9)-U9 | P9: 500 | Q9: =SUMIFS(tblDataPool[Price],tblDataPool[Project Role],B9,tblDataPool[Sub role],E9)-W9 | R9: 900 | T9: =SUMIFS(tblDataPool[Effort],tblDataPool[Project Role],B9,tblDataPool[Sub role],E9,tblDataPool[Item type],"Travel time") | U9: =SUMIFS(tblDataPool[Costs],tblDataPool[Project Role],B9,tblDataPool[Sub role],E9,tblDataPool[Item type],"Travel time") | V9: 500 | W9: =SUMIFS(tblDataPool[Price],tblDataPool[Project Role],B9,tblDataPool[Sub role],E9,tblDataPool[Item type],"Travel time") | X9: 450 | Z9: =Q9+W9-O9-U9 | AA9: =IF(OR(ST_Contractor=G9,AND(ST_AccountingRelatedCompany="yes",H9="yes")),Q9+W9,Z9) | AB9: =IF(OR(ST_Contractor=G9,AND(ST_AccountingRelatedCompany="yes",H9="yes")),N9+T9,0) | AC9: =IF(AB9>0,AA9/AB9,0)
A10: R-3 | B10: Developer | C10: Senior | D10: Backend development #1: Content types, migrations, Keycloak SSO, Fiona API | E10: 1 | F10: 1 | G10: any | H10: =_xlfn.XLOOKUP(G10,tblCompanies[Company],tblCompanies[Accounting-related company],"") | I10: any | J10: =_xlfn.XLOOKUP(I10,tblCountries[Country],tblCountries[Inflation rate],0) | K10: any | L10: high | N10: =SUMIFS(tblDataPool[Effort],tblDataPool[Project Role],B10,tblDataPool[Sub role],E10)-T10 | O10: =SUMIFS(tblDataPool[Costs],tblDataPool[Project Role],B10,tblDataPool[Sub role],E10)-U10 | P10: 500 | Q10: =SUMIFS(tblDataPool[Price],tblDataPool[Project Role],B10,tblDataPool[Sub role],E10)-W10 | R10: 900 | T10: =SUMIFS(tblDataPool[Effort],tblDataPool[Project Role],B10,tblDataPool[Sub role],E10,tblDataPool[Item type],"Travel time") | U10: =SUMIFS(tblDataPool[Costs],tblDataPool[Project Role],B10,tblDataPool[Sub role],E10,tblDataPool[Item type],"Travel time") | V10: 500 | W10: =SUMIFS(tblDataPool[Price],tblDataPool[Project Role],B10,tblDataPool[Sub role],E10,tblDataPool[Item type],"Travel time") | X10: 450 | Z10: =Q10+W10-O10-U10 | AA10: =IF(OR(ST_Contractor=G10,AND(ST_AccountingRelatedCompany="yes",H10="yes")),Q10+W10,Z10) | AB10: =IF(OR(ST_Contractor=G10,AND(ST_AccountingRelatedCompany="yes",H10="yes")),N10+T10,0) | AC10: =IF(AB10>0,AA10/AB10,0)
A11: R-4 | B11: Developer | C11: Senior | D11: Backend development #2: Sony VOD, Solr search, mobile API, custom modules | E11: 1 | F11: 0 | G11: any | H11: =_xlfn.XLOOKUP(G11,tblCompanies[Company],tblCompanies[Accounting-related company],"") | I11: any | J11: =_xlfn.XLOOKUP(I11,tblCountries[Country],tblCountries[Inflation rate],0) | K11: any | L11: middle | N11: =SUMIFS(tblDataPool[Effort],tblDataPool[Project Role],B11,tblDataPool[Sub role],E11)-T11 | O11: =SUMIFS(tblDataPool[Costs],tblDataPool[Project Role],B11,tblDataPool[Sub role],E11)-U11 | P11: 500 | Q11: =SUMIFS(tblDataPool[Price],tblDataPool[Project Role],B11,tblDataPool[Sub role],E11)-W11 | R11: 900 | T11: =SUMIFS(tblDataPool[Effort],tblDataPool[Project Role],B11,tblDataPool[Sub role],E11,tblDataPool[Item type],"Travel time") | U11: =SUMIFS(tblDataPool[Costs],tblDataPool[Project Role],B11,tblDataPool[Sub role],E11,tblDataPool[Item type],"Travel time") | V11: 500 | W11: =SUMIFS(tblDataPool[Price],tblDataPool[Project Role],B11,tblDataPool[Sub role],E11,tblDataPool[Item type],"Travel time") | X11: 450 | Z11: =Q11+W11-O11-U11 | AA11: =IF(OR(ST_Contractor=G11,AND(ST_AccountingRelatedCompany="yes",H11="yes")),Q11+W11,Z11) | AB11: =IF(OR(ST_Contractor=G11,AND(ST_AccountingRelatedCompany="yes",H11="yes")),N11+T11,0) | AC11: =IF(AB11>0,AA11/AB11,0)
A12: R-5 | B12: Developer | C12: Middle | D12: Frontend development: Storybook components, Tailwind CSS, accessibility, responsive design | E12: 1 | F12: 1 | G12: any | H12: =_xlfn.XLOOKUP(G12,tblCompanies[Company],tblCompanies[Accounting-related company],"") | I12: any | J12: =_xlfn.XLOOKUP(I12,tblCountries[Country],tblCountries[Inflation rate],0) | K12: any | L12: high | N12: =SUMIFS(tblDataPool[Effort],tblDataPool[Project Role],B12,tblDataPool[Sub role],E12)-T12 | O12: =SUMIFS(tblDataPool[Costs],tblDataPool[Project Role],B12,tblDataPool[Sub role],E12)-U12 | P12: 500 | Q12: =SUMIFS(tblDataPool[Price],tblDataPool[Project Role],B12,tblDataPool[Sub role],E12)-W12 | R12: 900 | T12: =SUMIFS(tblDataPool[Effort],tblDataPool[Project Role],B12,tblDataPool[Sub role],E12,tblDataPool[Item type],"Travel time") | U12: =SUMIFS(tblDataPool[Costs],tblDataPool[Project Role],B12,tblDataPool[Sub role],E12,tblDataPool[Item type],"Travel time") | V12: 500 | W12: =SUMIFS(tblDataPool[Price],tblDataPool[Project Role],B12,tblDataPool[Sub role],E12,tblDataPool[Item type],"Travel time") | X12: 450 | Z12: =Q12+W12-O12-U12 | AA12: =IF(OR(ST_Contractor=G12,AND(ST_AccountingRelatedCompany="yes",H12="yes")),Q12+W12,Z12) | AB12: =IF(OR(ST_Contractor=G12,AND(ST_AccountingRelatedCompany="yes",H12="yes")),N12+T12,0) | AC12: =IF(AB12>0,AA12/AB12,0)
A13: R-6 | B13: UI/UX Designer | C13: Middle | D13: Design system, component wireframes, user flows, accessibility compliance | E13: 0.4 | F13: 0 | G13: any | H13: =_xlfn.XLOOKUP(G13,tblCompanies[Company],tblCompanies[Accounting-related company],"") | I13: any | J13: =_xlfn.XLOOKUP(I13,tblCountries[Country],tblCountries[Inflation rate],0) | K13: any | L13: low | N13: =SUMIFS(tblDataPool[Effort],tblDataPool[Project Role],B13,tblDataPool[Sub role],E13)-T13 | O13: =SUMIFS(tblDataPool[Costs],tblDataPool[Project Role],B13,tblDataPool[Sub role],E13)-U13 | P13: 500 | Q13: =SUMIFS(tblDataPool[Price],tblDataPool[Project Role],B13,tblDataPool[Sub role],E13)-W13 | R13: 900 | T13: =SUMIFS(tblDataPool[Effort],tblDataPool[Project Role],B13,tblDataPool[Sub role],E13,tblDataPool[Item type],"Travel time") | U13: =SUMIFS(tblDataPool[Costs],tblDataPool[Project Role],B13,tblDataPool[Sub role],E13,tblDataPool[Item type],"Travel time") | V13: 500 | W13: =SUMIFS(tblDataPool[Price],tblDataPool[Project Role],B13,tblDataPool[Sub role],E13,tblDataPool[Item type],"Travel time") | X13: 450 | Z13: =Q13+W13-O13-U13 | AA13: =IF(OR(ST_Contractor=G13,AND(ST_AccountingRelatedCompany="yes",H13="yes")),Q13+W13,Z13) | AB13: =IF(OR(ST_Contractor=G13,AND(ST_AccountingRelatedCompany="yes",H13="yes")),N13+T13,0) | AC13: =IF(AB13>0,AA13/AB13,0)
A14: R-7 | B14: DevOps Engineer | C14: Middle | D14: Azure infrastructure, CI/CD pipelines, monitoring, performance optimization | E14: 0.5 | F14: 1 | G14: any | H14: =_xlfn.XLOOKUP(G14,tblCompanies[Company],tblCompanies[Accounting-related company],"") | I14: any | J14: =_xlfn.XLOOKUP(I14,tblCountries[Country],tblCountries[Inflation rate],0) | K14: any | L14: middle | N14: =SUMIFS(tblDataPool[Effort],tblDataPool[Project Role],B14,tblDataPool[Sub role],E14)-T14 | O14: =SUMIFS(tblDataPool[Costs],tblDataPool[Project Role],B14,tblDataPool[Sub role],E14)-U14 | P14: 500 | Q14: =SUMIFS(tblDataPool[Price],tblDataPool[Project Role],B14,tblDataPool[Sub role],E14)-W14 | R14: 900 | T14: =SUMIFS(tblDataPool[Effort],tblDataPool[Project Role],B14,tblDataPool[Sub role],E14,tblDataPool[Item type],"Travel time") | U14: =SUMIFS(tblDataPool[Costs],tblDataPool[Project Role],B14,tblDataPool[Sub role],E14,tblDataPool[Item type],"Travel time") | V14: 500 | W14: =SUMIFS(tblDataPool[Price],tblDataPool[Project Role],B14,tblDataPool[Sub role],E14,tblDataPool[Item type],"Travel time") | X14: 450 | Z14: =Q14+W14-O14-U14 | AA14: =IF(OR(ST_Contractor=G14,AND(ST_AccountingRelatedCompany="yes",H14="yes")),Q14+W14,Z14) | AB14: =IF(OR(ST_Contractor=G14,AND(ST_AccountingRelatedCompany="yes",H14="yes")),N14+T14,0) | AC14: =IF(AB14>0,AA14/AB14,0)
A15: R-8 | B15: Test Engineer | C15: Middle | D15: Test automation (Playwright), quality assurance, security testing, UAT coordination | E15: 0.5 | F15: 0 | G15: any | H15: =_xlfn.XLOOKUP(G15,tblCompanies[Company],tblCompanies[Accounting-related company],"") | I15: any | J15: =_xlfn.XLOOKUP(I15,tblCountries[Country],tblCountries[Inflation rate],0) | K15: any | L15: high | N15: =SUMIFS(tblDataPool[Effort],tblDataPool[Project Role],B15,tblDataPool[Sub role],E15)-T15 | O15: =SUMIFS(tblDataPool[Costs],tblDataPool[Project Role],B15,tblDataPool[Sub role],E15)-U15 | P15: 500 | Q15: =SUMIFS(tblDataPool[Price],tblDataPool[Project Role],B15,tblDataPool[Sub role],E15)-W15 | R15: 900 | T15: =SUMIFS(tblDataPool[Effort],tblDataPool[Project Role],B15,tblDataPool[Sub role],E15,tblDataPool[Item type],"Travel time") | U15: =SUMIFS(tblDataPool[Costs],tblDataPool[Project Role],B15,tblDataPool[Sub role],E15,tblDataPool[Item type],"Travel time") | V15: 500 | W15: =SUMIFS(tblDataPool[Price],tblDataPool[Project Role],B15,tblDataPool[Sub role],E15,tblDataPool[Item type],"Travel time") | X15: 450 | Z15: =Q15+W15-O15-U15 | AA15: =IF(OR(ST_Contractor=G15,AND(ST_AccountingRelatedCompany="yes",H15="yes")),Q15+W15,Z15) | AB15: =IF(OR(ST_Contractor=G15,AND(ST_AccountingRelatedCompany="yes",H15="yes")),N15+T15,0) | AC15: =IF(AB15>0,AA15/AB15,0)
A16: 5 | B16: UI/UX Designer | C16: 5 | D16: 8 | E16: UI/UX Designer (Junior) | F16: 0 | G16: any | H16: =_xlfn.XLOOKUP(G16,tblCompanies[Company],tblCompanies[Accounting-related company],"") | I16: any | J16: =_xlfn.XLOOKUP(I16,tblCountries[Country],tblCountries[Inflation rate],0) | K16: any | L16: low | N16: =SUMIFS(tblDataPool[Effort],tblDataPool[Project Role],B16,tblDataPool[Sub role],E16)-T16 | O16: =SUMIFS(tblDataPool[Costs],tblDataPool[Project Role],B16,tblDataPool[Sub role],E16)-U16 | P16: 500 | Q16: =SUMIFS(tblDataPool[Price],tblDataPool[Project Role],B16,tblDataPool[Sub role],E16)-W16 | R16: 900 | T16: =SUMIFS(tblDataPool[Effort],tblDataPool[Project Role],B16,tblDataPool[Sub role],E16,tblDataPool[Item type],"Travel time") | U16: =SUMIFS(tblDataPool[Costs],tblDataPool[Project Role],B16,tblDataPool[Sub role],E16,tblDataPool[Item type],"Travel time") | V16: 500 | W16: =SUMIFS(tblDataPool[Price],tblDataPool[Project Role],B16,tblDataPool[Sub role],E16,tblDataPool[Item type],"Travel time") | X16: 450 | Z16: =Q16+W16-O16-U16 | AA16: =IF(OR(ST_Contractor=G16,AND(ST_AccountingRelatedCompany="yes",H16="yes")),Q16+W16,Z16) | AB16: =IF(OR(ST_Contractor=G16,AND(ST_AccountingRelatedCompany="yes",H16="yes")),N16+T16,0) | AC16: =IF(AB16>0,AA16/AB16,0)
A17: 5 | B17: UI/UX Designer | C17: 5 | D17: 9 | E17: UI/UX Designer (Middle) | F17: 1 | G17: any | H17: =_xlfn.XLOOKUP(G17,tblCompanies[Company],tblCompanies[Accounting-related company],"") | I17: any | J17: =_xlfn.XLOOKUP(I17,tblCountries[Country],tblCountries[Inflation rate],0) | K17: any | L17: middle | N17: =SUMIFS(tblDataPool[Effort],tblDataPool[Project Role],B17,tblDataPool[Sub role],E17)-T17 | O17: =SUMIFS(tblDataPool[Costs],tblDataPool[Project Role],B17,tblDataPool[Sub role],E17)-U17 | P17: 500 | Q17: =SUMIFS(tblDataPool[Price],tblDataPool[Project Role],B17,tblDataPool[Sub role],E17)-W17 | R17: 900 | T17: =SUMIFS(tblDataPool[Effort],tblDataPool[Project Role],B17,tblDataPool[Sub role],E17,tblDataPool[Item type],"Travel time") | U17: =SUMIFS(tblDataPool[Costs],tblDataPool[Project Role],B17,tblDataPool[Sub role],E17,tblDataPool[Item type],"Travel time") | V17: 500 | W17: =SUMIFS(tblDataPool[Price],tblDataPool[Project Role],B17,tblDataPool[Sub role],E17,tblDataPool[Item type],"Travel time") | X17: 450 | Z17: =Q17+W17-O17-U17 | AA17: =IF(OR(ST_Contractor=G17,AND(ST_AccountingRelatedCompany="yes",H17="yes")),Q17+W17,Z17) | AB17: =IF(OR(ST_Contractor=G17,AND(ST_AccountingRelatedCompany="yes",H17="yes")),N17+T17,0) | AC17: =IF(AB17>0,AA17/AB17,0)
A18: 5 | B18: UI/UX Designer | C18: 5 | D18: 10 | E18: UI/UX Designer (Senior) | F18: 0 | G18: any | H18: =_xlfn.XLOOKUP(G18,tblCompanies[Company],tblCompanies[Accounting-related company],"") | I18: any | J18: =_xlfn.XLOOKUP(I18,tblCountries[Country],tblCountries[Inflation rate],0) | K18: any | L18: high | N18: =SUMIFS(tblDataPool[Effort],tblDataPool[Project Role],B18,tblDataPool[Sub role],E18)-T18 | O18: =SUMIFS(tblDataPool[Costs],tblDataPool[Project Role],B18,tblDataPool[Sub role],E18)-U18 | P18: 500 | Q18: =SUMIFS(tblDataPool[Price],tblDataPool[Project Role],B18,tblDataPool[Sub role],E18)-W18 | R18: 900 | T18: =SUMIFS(tblDataPool[Effort],tblDataPool[Project Role],B18,tblDataPool[Sub role],E18,tblDataPool[Item type],"Travel time") | U18: =SUMIFS(tblDataPool[Costs],tblDataPool[Project Role],B18,tblDataPool[Sub role],E18,tblDataPool[Item type],"Travel time") | V18: 500 | W18: =SUMIFS(tblDataPool[Price],tblDataPool[Project Role],B18,tblDataPool[Sub role],E18,tblDataPool[Item type],"Travel time") | X18: 450 | Z18: =Q18+W18-O18-U18 | AA18: =IF(OR(ST_Contractor=G18,AND(ST_AccountingRelatedCompany="yes",H18="yes")),Q18+W18,Z18) | AB18: =IF(OR(ST_Contractor=G18,AND(ST_AccountingRelatedCompany="yes",H18="yes")),N18+T18,0) | AC18: =IF(AB18>0,AA18/AB18,0)
A19: 6 | B19: Test manager | C19: 6 | D19: 11 | E19: Test manager | F19: 1 | G19: any | H19: =_xlfn.XLOOKUP(G19,tblCompanies[Company],tblCompanies[Accounting-related company],"") | I19: any | J19: =_xlfn.XLOOKUP(I19,tblCountries[Country],tblCountries[Inflation rate],0) | K19: any | L19: high | N19: =SUMIFS(tblDataPool[Effort],tblDataPool[Project Role],B19,tblDataPool[Sub role],E19)-T19 | O19: =SUMIFS(tblDataPool[Costs],tblDataPool[Project Role],B19,tblDataPool[Sub role],E19)-U19 | P19: 500 | Q19: =SUMIFS(tblDataPool[Price],tblDataPool[Project Role],B19,tblDataPool[Sub role],E19)-W19 | R19: 900 | T19: =SUMIFS(tblDataPool[Effort],tblDataPool[Project Role],B19,tblDataPool[Sub role],E19,tblDataPool[Item type],"Travel time") | U19: =SUMIFS(tblDataPool[Costs],tblDataPool[Project Role],B19,tblDataPool[Sub role],E19,tblDataPool[Item type],"Travel time") | V19: 500 | W19: =SUMIFS(tblDataPool[Price],tblDataPool[Project Role],B19,tblDataPool[Sub role],E19,tblDataPool[Item type],"Travel time") | X19: 450 | Z19: =Q19+W19-O19-U19 | AA19: =IF(OR(ST_Contractor=G19,AND(ST_AccountingRelatedCompany="yes",H19="yes")),Q19+W19,Z19) | AB19: =IF(OR(ST_Contractor=G19,AND(ST_AccountingRelatedCompany="yes",H19="yes")),N19+T19,0) | AC19: =IF(AB19>0,AA19/AB19,0)
A20: 7 | B20: Test Engineer | C20: 7 | D20: 12 | E20: Test Engineer (Junior) | F20: 0 | G20: any | H20: =_xlfn.XLOOKUP(G20,tblCompanies[Company],tblCompanies[Accounting-related company],"") | I20: any | J20: =_xlfn.XLOOKUP(I20,tblCountries[Country],tblCountries[Inflation rate],0) | K20: any | L20: low | N20: =SUMIFS(tblDataPool[Effort],tblDataPool[Project Role],B20,tblDataPool[Sub role],E20)-T20 | O20: =SUMIFS(tblDataPool[Costs],tblDataPool[Project Role],B20,tblDataPool[Sub role],E20)-U20 | P20: 500 | Q20: =SUMIFS(tblDataPool[Price],tblDataPool[Project Role],B20,tblDataPool[Sub role],E20)-W20 | R20: 900 | T20: =SUMIFS(tblDataPool[Effort],tblDataPool[Project Role],B20,tblDataPool[Sub role],E20,tblDataPool[Item type],"Travel time") | U20: =SUMIFS(tblDataPool[Costs],tblDataPool[Project Role],B20,tblDataPool[Sub role],E20,tblDataPool[Item type],"Travel time") | V20: 500 | W20: =SUMIFS(tblDataPool[Price],tblDataPool[Project Role],B20,tblDataPool[Sub role],E20,tblDataPool[Item type],"Travel time") | X20: 450 | Z20: =Q20+W20-O20-U20 | AA20: =IF(OR(ST_Contractor=G20,AND(ST_AccountingRelatedCompany="yes",H20="yes")),Q20+W20,Z20) | AB20: =IF(OR(ST_Contractor=G20,AND(ST_AccountingRelatedCompany="yes",H20="yes")),N20+T20,0) | AC20: =IF(AB20>0,AA20/AB20,0)
A21: 7 | B21: Test Engineer | C21: 7 | D21: 13 | E21: Test engineer (Middle) | F21: 1 | G21: any | H21: =_xlfn.XLOOKUP(G21,tblCompanies[Company],tblCompanies[Accounting-related company],"") | I21: any | J21: =_xlfn.XLOOKUP(I21,tblCountries[Country],tblCountries[Inflation rate],0) | K21: any | L21: middle | N21: =SUMIFS(tblDataPool[Effort],tblDataPool[Project Role],B21,tblDataPool[Sub role],E21)-T21 | O21: =SUMIFS(tblDataPool[Costs],tblDataPool[Project Role],B21,tblDataPool[Sub role],E21)-U21 | P21: 500 | Q21: =SUMIFS(tblDataPool[Price],tblDataPool[Project Role],B21,tblDataPool[Sub role],E21)-W21 | R21: 900 | T21: =SUMIFS(tblDataPool[Effort],tblDataPool[Project Role],B21,tblDataPool[Sub role],E21,tblDataPool[Item type],"Travel time") | U21: =SUMIFS(tblDataPool[Costs],tblDataPool[Project Role],B21,tblDataPool[Sub role],E21,tblDataPool[Item type],"Travel time") | V21: 500 | W21: =SUMIFS(tblDataPool[Price],tblDataPool[Project Role],B21,tblDataPool[Sub role],E21,tblDataPool[Item type],"Travel time") | X21: 450 | Z21: =Q21+W21-O21-U21 | AA21: =IF(OR(ST_Contractor=G21,AND(ST_AccountingRelatedCompany="yes",H21="yes")),Q21+W21,Z21) | AB21: =IF(OR(ST_Contractor=G21,AND(ST_AccountingRelatedCompany="yes",H21="yes")),N21+T21,0) | AC21: =IF(AB21>0,AA21/AB21,0)
A22: 7 | B22: Test Engineer | C22: 7 | D22: 14 | E22: Test Engineer (Senior) | F22: 0 | G22: any | H22: =_xlfn.XLOOKUP(G22,tblCompanies[Company],tblCompanies[Accounting-related company],"") | I22: any | J22: =_xlfn.XLOOKUP(I22,tblCountries[Country],tblCountries[Inflation rate],0) | K22: any | L22: high | N22: =SUMIFS(tblDataPool[Effort],tblDataPool[Project Role],B22,tblDataPool[Sub role],E22)-T22 | O22: =SUMIFS(tblDataPool[Costs],tblDataPool[Project Role],B22,tblDataPool[Sub role],E22)-U22 | P22: 500 | Q22: =SUMIFS(tblDataPool[Price],tblDataPool[Project Role],B22,tblDataPool[Sub role],E22)-W22 | R22: 900 | T22: =SUMIFS(tblDataPool[Effort],tblDataPool[Project Role],B22,tblDataPool[Sub role],E22,tblDataPool[Item type],"Travel time") | U22: =SUMIFS(tblDataPool[Costs],tblDataPool[Project Role],B22,tblDataPool[Sub role],E22,tblDataPool[Item type],"Travel time") | V22: 500 | W22: =SUMIFS(tblDataPool[Price],tblDataPool[Project Role],B22,tblDataPool[Sub role],E22,tblDataPool[Item type],"Travel time") | X22: 450 | Z22: =Q22+W22-O22-U22 | AA22: =IF(OR(ST_Contractor=G22,AND(ST_AccountingRelatedCompany="yes",H22="yes")),Q22+W22,Z22) | AB22: =IF(OR(ST_Contractor=G22,AND(ST_AccountingRelatedCompany="yes",H22="yes")),N22+T22,0) | AC22: =IF(AB22>0,AA22/AB22,0)
A23: 8 | B23: Developer | C23: 8 | D23: 15 | E23: Developer (Junior) | F23: 0 | G23: any | H23: =_xlfn.XLOOKUP(G23,tblCompanies[Company],tblCompanies[Accounting-related company],"") | I23: any | J23: =_xlfn.XLOOKUP(I23,tblCountries[Country],tblCountries[Inflation rate],0) | K23: any | L23: low | N23: =SUMIFS(tblDataPool[Effort],tblDataPool[Project Role],B23,tblDataPool[Sub role],E23)-T23 | O23: =SUMIFS(tblDataPool[Costs],tblDataPool[Project Role],B23,tblDataPool[Sub role],E23)-U23 | P23: 500 | Q23: =SUMIFS(tblDataPool[Price],tblDataPool[Project Role],B23,tblDataPool[Sub role],E23)-W23 | R23: 900 | T23: =SUMIFS(tblDataPool[Effort],tblDataPool[Project Role],B23,tblDataPool[Sub role],E23,tblDataPool[Item type],"Travel time") | U23: =SUMIFS(tblDataPool[Costs],tblDataPool[Project Role],B23,tblDataPool[Sub role],E23,tblDataPool[Item type],"Travel time") | V23: 500 | W23: =SUMIFS(tblDataPool[Price],tblDataPool[Project Role],B23,tblDataPool[Sub role],E23,tblDataPool[Item type],"Travel time") | X23: 450 | Z23: =Q23+W23-O23-U23 | AA23: =IF(OR(ST_Contractor=G23,AND(ST_AccountingRelatedCompany="yes",H23="yes")),Q23+W23,Z23) | AB23: =IF(OR(ST_Contractor=G23,AND(ST_AccountingRelatedCompany="yes",H23="yes")),N23+T23,0) | AC23: =IF(AB23>0,AA23/AB23,0)
A24: 8 | B24: Developer | C24: 8 | D24: 16 | E24: Developer (Middle) | F24: 1 | G24: any | H24: =_xlfn.XLOOKUP(G24,tblCompanies[Company],tblCompanies[Accounting-related company],"") | I24: any | J24: =_xlfn.XLOOKUP(I24,tblCountries[Country],tblCountries[Inflation rate],0) | K24: any | L24: middle | N24: =SUMIFS(tblDataPool[Effort],tblDataPool[Project Role],B24,tblDataPool[Sub role],E24)-T24 | O24: =SUMIFS(tblDataPool[Costs],tblDataPool[Project Role],B24,tblDataPool[Sub role],E24)-U24 | P24: 900 | Q24: =SUMIFS(tblDataPool[Price],tblDataPool[Project Role],B24,tblDataPool[Sub role],E24)-W24 | R24: 900 | T24: =SUMIFS(tblDataPool[Effort],tblDataPool[Project Role],B24,tblDataPool[Sub role],E24,tblDataPool[Item type],"Travel time") | U24: =SUMIFS(tblDataPool[Costs],tblDataPool[Project Role],B24,tblDataPool[Sub role],E24,tblDataPool[Item type],"Travel time") | V24: 900 | W24: =SUMIFS(tblDataPool[Price],tblDataPool[Project Role],B24,tblDataPool[Sub role],E24,tblDataPool[Item type],"Travel time") | X24: 450 | Z24: =Q24+W24-O24-U24 | AA24: =IF(OR(ST_Contractor=G24,AND(ST_AccountingRelatedCompany="yes",H24="yes")),Q24+W24,Z24) | AB24: =IF(OR(ST_Contractor=G24,AND(ST_AccountingRelatedCompany="yes",H24="yes")),N24+T24,0) | AC24: =IF(AB24>0,AA24/AB24,0)
A25: 8 | B25: Developer | C25: 8 | D25: 17 | E25: Developer (Senior) | F25: 0 | G25: any | H25: =_xlfn.XLOOKUP(G25,tblCompanies[Company],tblCompanies[Accounting-related company],"") | I25: any | J25: =_xlfn.XLOOKUP(I25,tblCountries[Country],tblCountries[Inflation rate],0) | K25: any | L25: high | N25: =SUMIFS(tblDataPool[Effort],tblDataPool[Project Role],B25,tblDataPool[Sub role],E25)-T25 | O25: =SUMIFS(tblDataPool[Costs],tblDataPool[Project Role],B25,tblDataPool[Sub role],E25)-U25 | P25: 500 | Q25: =SUMIFS(tblDataPool[Price],tblDataPool[Project Role],B25,tblDataPool[Sub role],E25)-W25 | R25: 900 | T25: =SUMIFS(tblDataPool[Effort],tblDataPool[Project Role],B25,tblDataPool[Sub role],E25,tblDataPool[Item type],"Travel time") | U25: =SUMIFS(tblDataPool[Costs],tblDataPool[Project Role],B25,tblDataPool[Sub role],E25,tblDataPool[Item type],"Travel time") | V25: 500 | W25: =SUMIFS(tblDataPool[Price],tblDataPool[Project Role],B25,tblDataPool[Sub role],E25,tblDataPool[Item type],"Travel time") | X25: 450 | Z25: =Q25+W25-O25-U25 | AA25: =IF(OR(ST_Contractor=G25,AND(ST_AccountingRelatedCompany="yes",H25="yes")),Q25+W25,Z25) | AB25: =IF(OR(ST_Contractor=G25,AND(ST_AccountingRelatedCompany="yes",H25="yes")),N25+T25,0) | AC25: =IF(AB25>0,AA25/AB25,0)
A26: 9 | B26: DevOps Engineer | C26: 9 | D26: 18 | E26: DevOps Engineer | F26: 1 | G26: any | H26: =_xlfn.XLOOKUP(G26,tblCompanies[Company],tblCompanies[Accounting-related company],"") | I26: any | J26: =_xlfn.XLOOKUP(I26,tblCountries[Country],tblCountries[Inflation rate],0) | K26: any | L26: middle | N26: =SUMIFS(tblDataPool[Effort],tblDataPool[Project Role],B26,tblDataPool[Sub role],E26)-T26 | O26: =SUMIFS(tblDataPool[Costs],tblDataPool[Project Role],B26,tblDataPool[Sub role],E26)-U26 | P26: 500 | Q26: =SUMIFS(tblDataPool[Price],tblDataPool[Project Role],B26,tblDataPool[Sub role],E26)-W26 | R26: 900 | T26: =SUMIFS(tblDataPool[Effort],tblDataPool[Project Role],B26,tblDataPool[Sub role],E26,tblDataPool[Item type],"Travel time") | U26: =SUMIFS(tblDataPool[Costs],tblDataPool[Project Role],B26,tblDataPool[Sub role],E26,tblDataPool[Item type],"Travel time") | V26: 500 | W26: =SUMIFS(tblDataPool[Price],tblDataPool[Project Role],B26,tblDataPool[Sub role],E26,tblDataPool[Item type],"Travel time") | X26: 450 | Z26: =Q26+W26-O26-U26 | AA26: =IF(OR(ST_Contractor=G26,AND(ST_AccountingRelatedCompany="yes",H26="yes")),Q26+W26,Z26) | AB26: =IF(OR(ST_Contractor=G26,AND(ST_AccountingRelatedCompany="yes",H26="yes")),N26+T26,0) | AC26: =IF(AB26>0,AA26/AB26,0)
B27: Last row. Don't override this row. Only use menu item above "Edit project roles" or "Edit sub roles".

Sheet Other costs
A1: Other costs
A2: =Start!A2
A4: ID | B4: Description | C4: Assumptions | D4: ="Costs [" & CF_Currency & "]" | E4: ="Costs to be charged [" & CF_Currency & "]"
D5: =SUBTOTAL(9,D6:D36) | E5: =SUBTOTAL(9,E6:E36)
A6: C-10 | B6: Travel Costs | E6: =$D$6
A7: C-20 | E7: =$D$7
A8: C-30 | E8: =$D$8
A9: C-40 | E9: =$D$9
A10: C-50 | E10: =$D$10
A11: C-60 | E11: =$D$11
A12: C-70 | E12: =$D$12
A13: C-80 | E13: =$D$13
A14: C-90 | E14: =$D$14
A15: C-100 | E15: =$D$15
A16: C-110 | E16: =$D$16
A17: C-120 | E17: =$D$17
A18: C-130 | E18: =$D$18
A19: C-140 | E19: =$D$19
A20: C-150 | E20: =$D$20
A21: C-160 | E21: =$D$21
A22: C-170 | E22: =$D$22
A23: C-180 | E23: =$D$23
A24: C-190 | E24: =$D$24
A25: C-200 | E25: =$D$25
A26: C-210 | E26: =$D$26
A27: C-220 | E27: =$D$27
A28: C-230 | E28: =$D$28
A29: C-240 | E29: =$D$29
A30: C-250 | E30: =$D$30
A31: C-260 | E31: =$D$31
A32: C-270 | E32: =$D$32
A33: C-280 | E33: =$D$33
A34: C-290 | E34: =$D$34
A35: C-300 | E35: =$D$35
A36: Last row. Don't override this row. New rows cannot be inserted oder added.
D38: Costs to be charged (without travel costs): | E38: =E5-E6

Sheet Change history
A1: History of changes
A2: =Start!A2
A4: Changes are entered automatically! But you can also add your own entries. Please use the tabulator key in the last column of the last row for adding a new row.
A5: Date of change | B5: Description | C5: Author
A6: 28.03.2025 | B6: Preparation: total effort (without risks) = 0,00 days, feature effort = 0,00 days, weighted risk impact = 0,00 days, total price = 0,00 €, total adjusted price = 0,00 € | C6: g.wichert
A7: 10.11.2025 | B7: Preparation: total effort (without risks) = 0,00 days, feature effort = 0,00 days, weighted risk impact = 0,00 days, total price = 0,00 €, total adjusted price = 0,00 €

Sheet Summary
A1: Summary | D1: ="Gross profit ratio [" & CF_Currency & "/day]:" | E1: =IFERROR(GETPIVOTDATA("Total Gross profit",$A$18)/GETPIVOTDATA("Total Effort Contractor",$A$18),0)
A2: =Start!A2 | D2: ="Gross profit ratio [" & CF_Currency & "/hour]:" | E2: =E1/8
G3: Use menu above "Confirm adjusted total price" to adjust all daily rates.
A4: Position | B4: Total effort | D4: ="Avg. daily rate [" & CF_Currency & "]" | E4: ="Total price [" & CF_Currency & "]" | G4: ="Adjusted total price [" & CF_Currency & "]" | H4: Difference
B5: =SUBTOTAL(9,B6:B12)-B7 | C5: =SUBTOTAL(9,C6:C12)-C7 | E5: =SUBTOTAL(9,E6:E12)-E7 | F5: =IF(ABS(E5-G5)<0.001,1,0) | G5: =$E$5
A6: Project tasks and features | B6: =GT_EffortWithoutWAAndTTAndRisks | C6: =IFERROR(B6/$B$5,0) | D6: ='Project roles'!$R$8 | E6: =B6*D6 | G6: =B6*D6*(100%+H6) | H6: =IFERROR((G5-E10-E12)/(E5-E10-E12)-100%,0)
A7: included optional tasks | B7: ='Project tasks'!J78 | D7: ='Project roles'!$R$8 | E7: =B7*D7 | G7: =B7*D7*(100%+H7) | H7: =H6
A8: Risks | B8: ='Project tasks'!J75 | C8: =IFERROR(B8/$B$5,0) | D8: ='Project roles'!$R$8 | E8: =B8*D8 | G8: =B8*D8*(100%+H8) | H8: =H6
A9: Travel time | B9: ='Project tasks'!J73 | C9: =IFERROR(B9/$B$5,0) | D9: ='Project roles'!X8 | E9: =B9*D9 | G9: =B9*D9*(100%+H9) | H9: =H6
A10: Travel costs | E10: ='Other costs'!E6 | G10: =E10 | H10: 0
A11: Warranty | B11: ='Project tasks'!J74 | C11: =IFERROR(B11/$B$5,0) | D11: ='Project roles'!$R$8 | E11: =B11*D11 | G11: =B11*D11*(100%+H11) | H11: =H8
A12: Other costs (without travel costs) | E12: ='Other costs'!E38 | G12: =E12 | H12: 0
A15: The following pivot tables show the costs and price structure from different perspectives:
C17: Costs without inflation. Use menu above 'Edit options' to change this option.
A18: Item Type | B18: Total effort | C18: Total Costs | D18: Total Price | E18: Total Margin | F18: Total Gross profit | G18: Total Effort Contractor
A19: Task | B19: 0 | C19: 0 | D19: 0 | E19: 0 | F19: 0 | G19: 0
A20: Travel time | B20: 0 | C20: 0 | D20: 0 | E20: 0 | F20: 0 | G20: 0
A21: Warranty | B21: 0 | C21: 0 | D21: 0 | E21: 0 | F21: 0 | G21: 0
A22: Gesamtergebnis | B22: 0 | C22: 0 | D22: 0 | E22: 0 | F22: 0 | G22: 0
E29: =SU_Info
A30: Task group | B30: Summary task | C30: Item type | D30: Total effort | E30: Total Costs | F30: Total Price | G30: Total Margin | I30: Feature group | J30: Feature sub group | K30: Item type | L30: Total effort
A31: (Leer) | B31: Gewährleistung | C31: Warranty | D31: 0 | E31: 0 | F31: 0 | G31: 0 | I31: (Leer) | J31: (Leer) | K31: Task | L31: 0
B32: Implementierung | C32: Task | D32: 0 | E32: 0 | F32: 0 | G32: 0 | K32: Travel time | L32: 0
B33: Inititialisierung | C33: Task | D33: 0 | E33: 0 | F33: 0 | G33: 0 | K33: Warranty | L33: 0
B34: Übergreifende Aufgaben | C34: Task | D34: 0 | E34: 0 | F34: 0 | G34: 0 | I34: Gesamtergebnis | L34: 0
C35: Travel time | D35: 0 | E35: 0 | F35: 0 | G35: 0
A36: Gesamtergebnis | D36: 0 | E36: 0 | F36: 0 | G36: 0

Sheet Chart | GANTT
A1: GANTT Chart | D1: Use the menu above "Refresh tables/charts" to rebuild this chart.
A2: =Start!A2
A4: Task group | B4: Summary task | C4: ID | D4: Task | E4: Start | F4: Duration | G4: Dependency | H4: Finish

Sheet Chart | Risks
A1: Risks Chart | D1: Use the menu above "Refresh tables/charts" to rebuild this chart.
A2: =Start!A2
O4: ID | P4: Risk title | Q4: Risk likelihood | R4: Risk impact | S4: Weighted risk impact
O6: Ergebnis | S6: =SUBTOTAL(109,tblRisksForChart[Weighted risk impact])

Sheet Data pool
A1: Data pool | C1: 25 / 23 | D1: 32 / 30
A2: =Start!A2
A4: 0 | B4: 1 | D4: 2 | E4: 3 | F4: 4 | I4: 8 | J4: 5 | K4: 6 | L4: 7 | M4: 9 | N4: 10 | O4: 11 | P4: 12 | Q4: 13 | R4: 14 | S4: 15 | T4: 16 | U4: 17 | V4: 18 | W4: 19 | X4: 20 | Y4: 21 | Z4: 22 | AA4: 23 | AJ4: 24 | AK4: 25 | AL4: 26 | AM4: 27 | AN4: 28 | AO4: 29 | AP4: 30 | AQ4: 31
A5: Item type | B5: Task id | C5: Task group | D5: Summary task | E5: Task | F5: Feature id | G5: Feature range | H5: Feature group | I5: Feature sub group | J5: Feature task no | K5: Feature | L5: Sub feature | M5: Costs id | N5: Cost descr | O5: Assumptions | P5: Ref. id | Q5: Risks | R5: Risk id | S5: Risk title | T5: Risk description | U5: Risk likelihood | V5: Risk likelihood (first team) | W5: Risk likelihood (second team) | X5: Risk impact | Y5: Risk impact (first team) | Z5: Risk impact (second team) | AA5: Project Role | AB5: Sub role | AC5: Sub role percentage | AD5: Company | AE5: Country | AF5: Inflation rate | AG5: Location | AH5: Seniority Level | AI5: Period start | AJ5: Effort | AK5: Effort (first team) | AL5: Effort (second team) | AM5: Daily costs | AN5: Costs | AO5: Daily rate | AP5: Price | AQ5: Margin | AR5: Gross profit | AS5: Effort contractor
A6: Task | B6: P-10 | D6: Inititialisierung | E6: Projektinitialisierung und -planung | U6: 0 | V6: 0 | W6: 0 | X6: 0 | Y6: 0 | Z6: 0 | AA6: Any role | AB6: Any role | AC6: 1 | AD6: any | AE6: any | AF6: 0.02 | AG6: any | AH6: any | AJ6: 0 | AK6: 0 | AL6: 0 | AM6: 500 | AN6: 0 | AO6: 900 | AP6: 0 | AQ6: 0 | AR6: 0 | AS6: 0
A7: Task | B7: P-20 | D7: Inititialisierung | E7: Planung und Durchführung Projekt Kick Off-Meeting | U7: 0 | V7: 0 | W7: 0 | X7: 0 | Y7: 0 | Z7: 0 | AA7: Any role | AB7: Any role | AC7: 1 | AD7: any | AE7: any | AF7: 0.02 | AG7: any | AH7: any | AJ7: 0 | AK7: 0 | AL7: 0 | AM7: 500 | AN7: 0 | AO7: 900 | AP7: 0 | AQ7: 0 | AR7: 0 | AS7: 0
A8: Task | B8: P-30 | D8: Inititialisierung | E8: Erstellung Software Architekturkonzept | U8: 0 | V8: 0 | W8: 0 | X8: 0 | Y8: 0 | Z8: 0 | AA8: Any role | AB8: Any role | AC8: 1 | AD8: any | AE8: any | AF8: 0.02 | AG8: any | AH8: any | AJ8: 0 | AK8: 0 | AL8: 0 | AM8: 500 | AN8: 0 | AO8: 900 | AP8: 0 | AQ8: 0 | AR8: 0 | AS8: 0
A9: Task | B9: P-40 | D9: Inititialisierung | E9: Erstellung Testkonzept | U9: 0 | V9: 0 | W9: 0 | X9: 0 | Y9: 0 | Z9: 0 | AA9: Any role | AB9: Any role | AC9: 1 | AD9: any | AE9: any | AF9: 0.02 | AG9: any | AH9: any | AJ9: 0 | AK9: 0 | AL9: 0 | AM9: 500 | AN9: 0 | AO9: 900 | AP9: 0 | AQ9: 0 | AR9: 0 | AS9: 0
A10: Task | B10: P-50 | D10: Inititialisierung | E10: Aufbau Entwicklungsumgebung | U10: 0 | V10: 0 | W10: 0 | X10: 0 | Y10: 0 | Z10: 0 | AA10: Any role | AB10: Any role | AC10: 1 | AD10: any | AE10: any | AF10: 0.02 | AG10: any | AH10: any | AJ10: 0 | AK10: 0 | AL10: 0 | AM10: 500 | AN10: 0 | AO10: 900 | AP10: 0 | AQ10: 0 | AR10: 0 | AS10: 0
A11: Task | B11: P-60 | D11: Implementierung | E11: Analyse & Software Design | U11: 0 | V11: 0 | W11: 0 | X11: 0 | Y11: 0 | Z11: 0 | AA11: Any role | AB11: Any role | AC11: 1 | AD11: any | AE11: any | AF11: 0.02 | AG11: any | AH11: any | AJ11: 0 | AK11: 0 | AL11: 0 | AM11: 500 | AN11: 0 | AO11: 900 | AP11: 0 | AQ11: 0 | AR11: 0 | AS11: 0
A12: Task | B12: P-70 | D12: Implementierung | E12: Software-entwicklung | U12: 0 | V12: 0 | W12: 0 | X12: 0 | Y12: 0 | Z12: 0 | AA12: Any role | AB12: Any role | AC12: 1 | AD12: any | AE12: any | AF12: 0.02 | AG12: any | AH12: any | AJ12: 0 | AK12: 0 | AL12: 0 | AM12: 500 | AN12: 0 | AO12: 900 | AP12: 0 | AQ12: 0 | AR12: 0 | AS12: 0
A13: Task | B13: P-80 | D13: Implementierung | E13: Softwaretest | U13: 0 | V13: 0 | W13: 0 | X13: 0 | Y13: 0 | Z13: 0 | AA13: Any role | AB13: Any role | AC13: 1 | AD13: any | AE13: any | AF13: 0.02 | AG13: any | AH13: any | AJ13: 0 | AK13: 0 | AL13: 0 | AM13: 500 | AN13: 0 | AO13: 900 | AP13: 0 | AQ13: 0 | AR13: 0 | AS13: 0
A14: Task | B14: P-90 | D14: Implementierung | E14: Entwicklung und Wartung Testautomatisierung | U14: 0 | V14: 0 | W14: 0 | X14: 0 | Y14: 0 | Z14: 0 | AA14: Any role | AB14: Any role | AC14: 1 | AD14: any | AE14: any | AF14: 0.02 | AG14: any | AH14: any | AJ14: 0 | AK14: 0 | AL14: 0 | AM14: 500 | AN14: 0 | AO14: 900 | AP14: 0 | AQ14: 0 | AR14: 0 | AS14: 0
A15: Task | B15: P-100 | D15: Implementierung | E15: Performance Test | U15: 0 | V15: 0 | W15: 0 | X15: 0 | Y15: 0 | Z15: 0 | AA15: Any role | AB15: Any role | AC15: 1 | AD15: any | AE15: any | AF15: 0.02 | AG15: any | AH15: any | AJ15: 0 | AK15: 0 | AL15: 0 | AM15: 500 | AN15: 0 | AO15: 900 | AP15: 0 | AQ15: 0 | AR15: 0 | AS15: 0
A16: Task | B16: P-110 | D16: Implementierung | E16: Sicherheitsprüfung | U16: 0 | V16: 0 | W16: 0 | X16: 0 | Y16: 0 | Z16: 0 | AA16: Any role | AB16: Any role | AC16: 1 | AD16: any | AE16: any | AF16: 0.02 | AG16: any | AH16: any | AJ16: 0 | AK16: 0 | AL16: 0 | AM16: 500 | AN16: 0 | AO16: 900 | AP16: 0 | AQ16: 0 | AR16: 0 | AS16: 0
A17: Task | B17: P-120 | D17: Implementierung | E17: Erstellung Anwenderhandbuch | U17: 0 | V17: 0 | W17: 0 | X17: 0 | Y17: 0 | Z17: 0 | AA17: Any role | AB17: Any role | AC17: 1 | AD17: any | AE17: any | AF17: 0.02 | AG17: any | AH17: any | AJ17: 0 | AK17: 0 | AL17: 0 | AM17: 500 | AN17: 0 | AO17: 900 | AP17: 0 | AQ17: 0 | AR17: 0 | AS17: 0
... A29: Warranty | B29: P-250 | D29: Gewährleistung | E29: Gewährleistung | U29: 0 | V29: 0 | W29: 0 | X29: 0 | Y29: 0 | Z29: 0 | AA29: Any role | AB29: Any role | AC29: 1 | AD29: any | AE29: any | AF29: 0.02 | AG29: any | AH29: any | AJ29: 0 | AK29: 0 | AL29: 0 | AM29: 500 | AN29: 0 | AO29: 900 | AP29: 0 | AQ29: 0 | AR29: 0 | AS29: 0

Sheet Chart | Item types
A1: Item types
A2: =Start!A2
M4: Zeilenbeschriftungen | N4: _Price
M5: Task | N5: 0
M6: Travel time | N6: 0
M7: Warranty | N7: 0
M8: Gesamtergebnis | N8: 0

Sheet Pivot | Tasks
A1: Project tasks
A2: =Start!A2
A4: Task group | B4: Summary task | C4: Task | D4: Item type | E4: _Effort | F4: _Costs | G4: _Price | H4: _Margin
